Workbook
Name BudgetTitle: [1]Summary!$B$1
Name Percentage_of_Income_Spent: '[1]Chart Data'!$B$5
Name Title2: [1]!MonthlyIncome[[#Headers],[ITEM]]
Name Title2: [1]!MonthlyIncome[[#Headers],[ITEM]]
Name Title3: [1]!MonthlyExpenses[[#Headers],[ITEM]]
Name Title3: [1]!MonthlyExpenses[[#Headers],[ITEM]]
Name Title4: [1]!Savings[[#Headers],[DATE]]
Name Title4: [1]!Savings[[#Headers],[DATE]]
Name TotalMonthlyExpenses: [1]Summary!$C$6
Name TotalMonthlyIncome: [1]Summary!$C$4
Name TotalMonthlySavings: [1]Summary!$C$8

Sheet Overview
A1: Bank - Account | B1: balans op 1/1/2024 | C1: balans op 1/1/2025 | D1: balans op 1/1/2026 | E1: balans op 1/1/2027 | F1: balans op 1/1/2028
A2: Argenta - checking | B2: 5000
A3: Deutsche - savings | B3: 30000
A4: Deutsche - savings 2 | B4: 10000
A5: Deutsche - investment | B5: 10000
A6: Degiro - investment | B6: 5000

Sheet categories_cash book
A1: categorieën uitgaven
A2: Birthday/holiday
A3: Clothes
A4: Entertainment
A5: Free time spent
A6: Groceries
A7: Health
A8: Hobby's
A9: Insurance
A10: Investments
A11: Job
A12: Other
... A19: Travel

Sheet cash book - Argenta
A1: Date | B1: Month | C1: Year | D1: Description | E1: Category | F1: Income | G1: Expenses | H1: Balance
A2: 45292 | B2: =MONTH('cash book - Argenta'!$A2) -> 1 | C2: =YEAR(A2) -> 2024 | E2: Huur | H2: =Overview!B2 -> 5000
A3: 45294 | B3: =MONTH('cash book - Argenta'!$A3) -> 1 | C3: =YEAR(A3) -> 2024 | E3: Belegging | G3: 1200 | H3: =H2+F3-G3 -> 3800
A4: 45294 | B4: =MONTH('cash book - Argenta'!$A4) -> 1 | C4: =YEAR(A4) -> 2024 | E4: Spaar | G4: 300 | H4: =H3+F4-G4 -> 3500
A5: 45296 | B5: =MONTH('cash book - Argenta'!$A5) -> 1 | C5: =YEAR(A5) -> 2024 | E5: Persoonlijke verzorging | G5: 45 | H5: =H4+F5-G5 -> 3455
A6: 45303 | B6: =MONTH('cash book - Argenta'!$A6) -> 1 | C6: =YEAR(A6) -> 2024 | E6: Persoonlijke verzorging | G6: 30 | H6: =H5+F6-G6 -> 3425
A7: 45303 | B7: =MONTH('cash book - Argenta'!$A7) -> 1 | C7: =YEAR(A7) -> 2024 | E7: Boodschappen | G7: 400 | H7: =H6+F7-G7 -> 3025
A8: 45303 | B8: =MONTH('cash book - Argenta'!$A8) -> 1 | C8: =YEAR(A8) -> 2024 | E8: Boodschappen | G8: 300 | H8: =H7+F8-G8 -> 2725
A9: 45306 | B9: =MONTH('cash book - Argenta'!$A9) -> 1 | C9: =YEAR(A9) -> 2024 | E9: Kleding | G9: 200 | H9: =H8+F9-G9 -> 2525
A10: 45310 | B10: =MONTH('cash book - Argenta'!$A10) -> 1 | C10: =YEAR(A10) -> 2024 | E10: Entertainment | G10: 30 | H10: =H9+F10-G10 -> 2495
A11: 45316 | B11: =MONTH('cash book - Argenta'!$A11) -> 1 | C11: =YEAR(A11) -> 2024 | E11: Hobby's | G11: 100 | H11: =H10+F11-G11 -> 2395
A12: 45316 | B12: =MONTH('cash book - Argenta'!$A12) -> 1 | C12: =YEAR(A12) -> 2024 | E12: Hobby's | G12: 15 | H12: =H11+F12-G12 -> 2380
A13: 45316 | B13: =MONTH('cash book - Argenta'!$A13) -> 1 | C13: =YEAR(A13) -> 2024 | E13: Kleding | G13: 50 | H13: =H12+F13-G13 -> 2330
A14: 45317 | B14: =MONTH('cash book - Argenta'!$A14) -> 1 | C14: =YEAR(A14) -> 2024 | E14: Entertainment | G14: 15 | H14: =H13+F14-G14 -> 2315
... A20: 45319 | B20: =MONTH('cash book - Argenta'!$A20) -> 1 | C20: =YEAR(A20) -> 2024 | E20: Kleding | G20: 90 | H20: =H19+F20-G20 -> 2025
A21: 45320 | B21: =MONTH('cash book - Argenta'!$A21) -> 1 | C21: =YEAR(A21) -> 2024 | E21: Job | F21: 3000 | H21: =H20+F21-G21 -> 5025
A22: 45324 | B22: =MONTH('cash book - Argenta'!$A22) -> 2 | C22: =YEAR(A22) -> 2024 | H22: =H21+F22-G22 -> 5025
A23: 45325 | B23: =MONTH('cash book - Argenta'!$A23) -> 2 | C23: =YEAR(A23) -> 2024 | H23: =H22+F23-G23 -> 5025
A24: 45325 | B24: =MONTH('cash book - Argenta'!$A24) -> 2 | C24: =YEAR(A24) -> 2024 | H24: =H23+F24-G24 -> 5025
A25: 45325 | B25: =MONTH('cash book - Argenta'!$A25) -> 2 | C25: =YEAR(A25) -> 2024 | H25: =H24+F25-G25 -> 5025
A26: 45327 | B26: =MONTH('cash book - Argenta'!$A26) -> 2 | C26: =YEAR(A26) -> 2024 | H26: =H25+F26-G26 -> 5025
A27: 45327 | B27: =MONTH('cash book - Argenta'!$A27) -> 2 | C27: =YEAR(A27) -> 2024 | H27: =H26+F27-G27 -> 5025
A28: 45329 | B28: =MONTH('cash book - Argenta'!$A28) -> 2 | C28: =YEAR(A28) -> 2024 | H28: =H27+F28-G28 -> 5025
A29: 45329 | B29: =MONTH('cash book - Argenta'!$A29) -> 2 | C29: =YEAR(A29) -> 2024 | H29: =H28+F29-G29 -> 5025
A30: 45330 | B30: =MONTH('cash book - Argenta'!$A30) -> 2 | C30: =YEAR(A30) -> 2024 | H30: =H29+F30-G30 -> 5025
A31: 45332 | B31: =MONTH('cash book - Argenta'!$A31) -> 2 | C31: =YEAR(A31) -> 2024 | H31: =H30+F31-G31 -> 5025
A32: 45334 | B32: =MONTH('cash book - Argenta'!$A32) -> 2 | C32: =YEAR(A32) -> 2024 | H32: =H31+F32-G32 -> 5025
A33: 45336 | B33: =MONTH('cash book - Argenta'!$A33) -> 2 | C33: =YEAR(A33) -> 2024 | H33: =H32+F33-G33 -> 5025
... A94: 45404 | B94: =MONTH('cash book - Argenta'!$A94) -> 4 | C94: =YEAR(A94) -> 2024 | H94: =H93+F94-G94 -> 5025
A95: 45407 | B95: =MONTH('cash book - Argenta'!$A95) -> 4 | C95: =YEAR(A95) -> 2024 | H95: =H94+'cash book - Argenta'!$F95-'cash book - Argenta'!$G95 -> 5025
A96: 45408 | B96: =MONTH('cash book - Argenta'!$A96) -> 4 | C96: =YEAR(A96) -> 2024 | H96: =H95+'cash book - Argenta'!$F96-'cash book - Argenta'!$G96 -> 5025
A97: 45409 | B97: =MONTH('cash book - Argenta'!$A97) -> 4 | C97: =YEAR(A97) -> 2024 | H97: =H96+'cash book - Argenta'!$F97-'cash book - Argenta'!$G97 -> 5025
A98: 45409 | B98: =MONTH('cash book - Argenta'!$A98) -> 4 | C98: =YEAR(A98) -> 2024 | H98: =H97+'cash book - Argenta'!$F98-'cash book - Argenta'!$G98 -> 5025
A99: 45409 | B99: =MONTH('cash book - Argenta'!$A99) -> 4 | C99: =YEAR(A99) -> 2024 | H99: =H98+'cash book - Argenta'!$F99-'cash book - Argenta'!$G99 -> 5025
A100: 45409 | B100: =MONTH('cash book - Argenta'!$A100) -> 4 | C100: =YEAR(A100) -> 2024 | H100: =H99+'cash book - Argenta'!$F100-'cash book - Argenta'!$G100 -> 5025
A101: 45409 | B101: =MONTH('cash book - Argenta'!$A101) -> 4 | C101: =YEAR(A101) -> 2024 | H101: =H100+'cash book - Argenta'!$F101-'cash book - Argenta'!$G101 -> 5025
A102: 45409 | B102: =MONTH('cash book - Argenta'!$A102) -> 4 | C102: =YEAR(A102) -> 2024 | H102: =H101+'cash book - Argenta'!$F102-'cash book - Argenta'!$G102 -> 5025
A103: 45410 | B103: =MONTH('cash book - Argenta'!$A103) -> 4 | C103: =YEAR(A103) -> 2024 | H103: =H102+'cash book - Argenta'!$F103-'cash book - Argenta'!$G103 -> 5025
A104: 45410 | B104: =MONTH('cash book - Argenta'!$A104) -> 4 | C104: =YEAR(A104) -> 2024 | H104: =H103+'cash book - Argenta'!$F104-'cash book - Argenta'!$G104 -> 5025
A105: 45411 | B105: =MONTH('cash book - Argenta'!$A105) -> 4 | C105: =YEAR(A105) -> 2024 | H105: =H104+'cash book - Argenta'!$F105-'cash book - Argenta'!$G105 -> 5025
...

Sheet Pivot table
A1: Year | B1: (All)
A3: Row Labels | B3: Sum of Income | C3: Sum of Expenses
A4: Belegging | C4: 1200
A5: Boodschappen | C5: 740
A6: Entertainment | C6: 60
A7: Gezondheid | C7: 45
A8: Hobby's | C8: 115
A9: Hond | C9: 80
A10: Huur
A11: Job | B11: 3000
A12: Kleding | C12: 340
A13: Persoonlijke verzorging | C13: 95
A14: Spaar | C14: 300
A15: Grand Total | B15: 3000 | C15: 2975
